<?xml version="1.0" encoding="utf-8"?>
<robot name="tank" xmlns:xacro="http://ros.org/wiki/xacro">
  <link 
    name="dummy">
  </link>
  <joint name="dummy_joint" type="fixed">
    <parent link="dummy"/>
    <child link="core_link"/>
  </joint>
  <link
    name="core_link">
    <inertial>
      <origin
        xyz="-0.00011269 1.2452E-09 -0.033141"
        rpy="0 0 0" />
      <mass
        value="0.60403" />
      <inertia
        ixx="0.00036237"
        ixy="3.6922E-11"
        ixz="-6.0518E-11"
        iyy="0.00022509"
        iyz="-6.8687E-12"
        izz="0.00040708" />
    </inertial>
    <visual>
      <origin
        xyz="0 0 0"
        rpy="0 0 0" />
      <geometry>
        <mesh
          filename="package://tank/meshes/core_link.STL" />
      </geometry>
      <material
        name="">
        <color
          rgba="0.56471 0.56471 0.56471 1" />
      </material>
    </visual>
    <collision>
      <origin
        xyz="0 0 0"
        rpy="0 0 0" />
      <geometry>
        <mesh
          filename="package://tank/meshes/core_link.STL" />
      </geometry>
    </collision>
  </link>
  <gazebo reference="core_link">
  <material>Gazebo/Red</material>
  </gazebo>
  <link
    name="wheel_1">
    <inertial>
      <origin
        xyz="-0.01248 -2.5517E-08 -1.6458E-05"
        rpy="0 0 0" />
      <mass
        value="0.096925" />
      <inertia
        ixx="4.4379E-05"
        ixy="5.581E-13"
        ixz="-2.3462E-13"
        iyy="2.2503E-05"
        iyz="1.4393E-14"
        izz="2.2504E-05" />
    </inertial>
    <visual>
      <origin
        xyz="0 0 0"
        rpy="0 0 0" />
      <geometry>
        <mesh
          filename="package://tank/meshes/wheel_1.STL" />
      </geometry>
      <material
        name="">
        <color
          rgba="0.28235 0.28235 0.28235 1" />
      </material>
    </visual>
    <collision>
      <origin
        xyz="0 0 0"
        rpy="0 0 0" />
      <geometry>
        <mesh
          filename="package://tank/meshes/wheel_1.STL" />
      </geometry>
    </collision>
  </link>
  <joint
    name="wheel_1"
    type="continuous">
    <origin
      xyz="0.132 0 -0.0445"
      rpy="0 0 0" />
    <parent
      link="core_link" />
    <child
      link="wheel_1" />
    <axis
      xyz="-1 0 0" />
    <limit
      effort="10"
      velocity="10" />
    <dynamics
      damping="0.1"
      friction="0.1" />
  </joint>
  <link
    name="wheel_2">
    <inertial>
      <origin
        xyz="2.55166618823993E-08 1.64579697312234E-05 -0.0124800368672633"
        rpy="0 0 0" />
      <mass
        value="0.0969248758881471" />
      <inertia
        ixx="2.25033220760336E-05"
        ixy="1.43930304626409E-14"
        ixz="-5.58103400415268E-13"
        iyy="2.25037475309425E-05"
        iyz="2.34618173769376E-13"
        izz="4.43791952630414E-05" />
    </inertial>
    <visual>
      <origin
        xyz="0 0 0"
        rpy="0 0 0" />
      <geometry>
        <mesh
          filename="package://tank/meshes/wheel_2.STL" />
      </geometry>
      <material
        name="">
        <color
          rgba="1 1 1 1" />
      </material>
    </visual>
    <collision>
      <origin
        xyz="0 0 0"
        rpy="0 0 0" />
      <geometry>
        <mesh
          filename="package://tank/meshes/wheel_2.STL" />
      </geometry>
    </collision>
  </link>
  <joint
    name="wheel_2"
    type="continuous">
    <origin
      xyz="0 0.132 -0.0445"
      rpy="-1.5708 0 0" />
    <parent
      link="core_link" />
    <child
      link="wheel_2" />
    <axis
      xyz="0 0 -1" />
    <limit
      effort="10"
      velocity="10" />
    <dynamics
      damping="0.1"
      friction="0.1" />
  </joint>
  <link
    name="wheel_3">
    <inertial>
      <origin
        xyz="0.0124800368672634 2.55166619916869E-08 -1.64579697313344E-05"
        rpy="0 0 0" />
      <mass
        value="0.096924875888147" />
      <inertia
        ixx="4.43791952630414E-05"
        ixy="5.58103400840208E-13"
        ixz="2.34618173173316E-13"
        iyy="2.25033220760335E-05"
        iyz="-1.43930293191587E-14"
        izz="2.25037475309425E-05" />
    </inertial>
    <visual>
      <origin
        xyz="0 0 0"
        rpy="0 0 0" />
      <geometry>
        <mesh
          filename="package://tank/meshes/wheel_3.STL" />
      </geometry>
      <material
        name="">
        <color
          rgba="0.282352941176471 0.282352941176471 0.282352941176471 1" />
      </material>
    </visual>
    <collision>
      <origin
        xyz="0 0 0"
        rpy="0 0 0" />
      <geometry>
        <mesh
          filename="package://tank/meshes/wheel_3.STL" />
      </geometry>
    </collision>
  </link>
  <joint
    name="wheel_3"
    type="continuous">
    <origin
      xyz="-0.132 0 -0.0445"
      rpy="0 0 0" />
    <parent
      link="core_link" />
    <child
      link="wheel_3" />
    <axis
      xyz="1 0 0" />
    <limit
      effort="10"
      velocity="10" />
    <dynamics
      damping="0.1"
      friction="0.1" />
  </joint>
  <link
    name="wheel_4">
    <inertial>
      <origin
        xyz="-2.55166619483188E-08 1.64579697312581E-05 0.0124800368672634"
        rpy="0 0 0" />
      <mass
        value="0.0969248758881472" />
      <inertia
        ixx="2.25033220760335E-05"
        ixy="-1.43930303262096E-14"
        ixz="-5.58103400718429E-13"
        iyy="2.25037475309425E-05"
        iyz="-2.34618195303625E-13"
        izz="4.43791952630414E-05" />
    </inertial>
    <visual>
      <origin
        xyz="0 0 0"
        rpy="0 0 0" />
      <geometry>
        <mesh
          filename="package://tank/meshes/wheel_4.STL" />
      </geometry>
      <material
        name="">
        <color
          rgba="0.282352941176471 0.282352941176471 0.282352941176471 1" />
      </material>
    </visual>
    <collision>
      <origin
        xyz="0 0 0"
        rpy="0 0 0" />
      <geometry>
        <mesh
          filename="package://tank/meshes/wheel_4.STL" />
      </geometry>
    </collision>
  </link>
  <joint
    name="wheel_4"
    type="continuous">
    <origin
      xyz="0 -0.132 -0.0445"
      rpy="-1.5708 0 0" />
    <parent
      link="core_link" />
    <child
      link="wheel_4" />
    <axis
      xyz="0 0 1" />
    <limit
      effort="10"
      velocity="10" />
    <dynamics
      damping="0.1"
      friction="0.1" />
  </joint>
</robot>